Server ready at http://0.0.0.0:2002/
Server commands: [b]rowser, [q]uit
server> Server stopped
Traceback (most recent call last):
  File "/usr/lib/python3.7/runpy.py", line 193, in _run_module_as_main
    "__main__", mod_spec)
  File "/usr/lib/python3.7/runpy.py", line 85, in _run_code
    exec(code, run_globals)
  File "/usr/lib/python3.7/pydoc.py", line 2754, in <module>
    cli()
  File "/usr/lib/python3.7/pydoc.py", line 2699, in cli
    browse(port, hostname=hostname, open_browser=open_browser)
  File "/usr/lib/python3.7/pydoc.py", line 2609, in browse
    cmd = input('server> ')
OSError: [Errno 9] Bad file descriptor
Server ready at http://0.0.0.0:2002/
Server commands: [b]rowser, [q]uit
server> Server stopped
Traceback (most recent call last):
  File "/usr/lib/python3.7/runpy.py", line 193, in _run_module_as_main
    "__main__", mod_spec)
  File "/usr/lib/python3.7/runpy.py", line 85, in _run_code
    exec(code, run_globals)
  File "/usr/lib/python3.7/pydoc.py", line 2754, in <module>
    cli()
  File "/usr/lib/python3.7/pydoc.py", line 2699, in cli
    browse(port, hostname=hostname, open_browser=open_browser)
  File "/usr/lib/python3.7/pydoc.py", line 2609, in browse
    cmd = input('server> ')
OSError: [Errno 9] Bad file descriptor
Server ready at http://0.0.0.0:2002/
Server commands: [b]rowser, [q]uit
server> Server stopped
Traceback (most recent call last):
  File "/usr/lib/python3.7/runpy.py", line 193, in _run_module_as_main
    "__main__", mod_spec)
  File "/usr/lib/python3.7/runpy.py", line 85, in _run_code
    exec(code, run_globals)
  File "/usr/lib/python3.7/pydoc.py", line 2754, in <module>
    cli()
  File "/usr/lib/python3.7/pydoc.py", line 2699, in cli
    browse(port, hostname=hostname, open_browser=open_browser)
  File "/usr/lib/python3.7/pydoc.py", line 2609, in browse
    cmd = input('server> ')
OSError: [Errno 9] Bad file descriptor
